Workbook

Sheet Google Data
A1: Column1 | B1: Name | C1: Price | D1: Price Change | E1: Market Cap
A2: NVDA | B2: NVIDIA Corp | C2: 216.93 | D2: -0.16 | E2: 5228015397644 | G2: =Google_Data[[#This Row],[Market Cap]]/1000000000 -> 5228.0154
A3: DXCM | B3: DexCom Inc | C3: 85.54 | D3: -0.44 | E3: 32279434623 | G3: =Google_Data[[#This Row],[Market Cap]]/1000000000 -> 32.279435
A4: MNDY | B4: Monday.Com Ltd | C4: 100.59 | D4: 7.17 | E4: 4252352570 | G4: =Google_Data[[#This Row],[Market Cap]]/1000000000 -> 4.2523526
A5: STEM | B5: Stem Inc | C5: 3.54 | D5: 0.13 | E5: 34078673 | G5: =Google_Data[[#This Row],[Market Cap]]/1000000000 -> 0.034078673
A6: RUN | B6: Sunrun Inc | C6: 7.58 | D6: 0.69 | E6: 1825620241 | G6: =Google_Data[[#This Row],[Market Cap]]/1000000000 -> 1.8256202
A7: BLDP | B7: Ballard Power Systems Inc | C7: 1.53 | D7: 0.01 | E7: 537462673 | G7: =Google_Data[[#This Row],[Market Cap]]/1000000000 -> 0.53746267
A8: EVGO | B8: Evgo Inc | C8: 1.1 | D8: 0.04 | E8: 345967277 | G8: =Google_Data[[#This Row],[Market Cap]]/1000000000 -> 0.34596728
A9: COUR | B9: Coursera Inc | C9: 5.08 | D9: 0.07 | E9: 1341829949 | G9: =Google_Data[[#This Row],[Market Cap]]/1000000000 -> 1.3418299
A10: NNOX | B10: Nano-X Imaging Ltd | C10: 0.43 | D10: 0.02 | E10: 33958146 | G10: =Google_Data[[#This Row],[Market Cap]]/1000000000 -> 0.033958146
A11: FSLY | B11: Fastly Inc | C11: 22.12 | D11: -0.87 | E11: 3523716133 | G11: =Google_Data[[#This Row],[Market Cap]]/1000000000 -> 3.5237161

Sheet Stocks Dashboard
B2: Symbol | C2: Name | D2: Sector | E2: Cap Size | F2: # of Shares | G2: Price Paid Per Share | H2: Amount Paid | I2: Current Price | J2: Total Value | K2: Allocation | L2: Total Gain/ (Loss) $ | M2: Total Gain/ (Loss) % | N2: 1 Day Return $ | O2: 1 Day Return %
B3: ='Google Data'!A2 -> NVDA | C3: ='Google Data'!B2 -> NVIDIA Corp | D3: Technology | E3: =IF('Google Data'!G2>10,"Large",IF('Google Data'!G2>2,"Mid","Small")) -> Large | F3: 250 | G3: 174.39 | H3: =F3*G3 -> 43597.5 | I3: ='Google Data'!C2 -> 216.93 | J3: =F3*I3 -> 54232.5 | K3: =J3/$J$13 -> 0.27571875 | L3: =J3-H3 -> 10635 | M3: =L3/H3 -> 0.24393601 | N3: ='Google Data'!D2*'Stocks Dashboard'!F3 -> -40 | O3: ='Google Data'!C2/('Google Data'!C2-'Google Data'!D2)-1 -> -0.00073702151
B4: ='Google Data'!A3 -> DXCM | C4: ='Google Data'!B3 -> DexCom Inc | D4: Healthcare | E4: =IF('Google Data'!G3>10,"Large",IF('Google Data'!G3>2,"Mid","Small")) -> Large | F4: 250 | G4: 66.96 | H4: =F4*G4 -> 16740 | I4: ='Google Data'!C3 -> 85.54 | J4: =F4*I4 -> 21385 | K4: =J4/$J$13 -> 0.10872162 | L4: =J4-H4 -> 4645 | M4: =L4/H4 -> 0.27747909 | N4: ='Google Data'!D3*'Stocks Dashboard'!F4 -> -110 | O4: ='Google Data'!C3/('Google Data'!C3-'Google Data'!D3)-1 -> -0.0051174692
B5: ='Google Data'!A4 -> MNDY | C5: ='Google Data'!B4 -> Monday.Com Ltd | D5: Technology | E5: =IF('Google Data'!G4>10,"Large",IF('Google Data'!G4>2,"Mid","Small")) -> Mid | F5: 750 | G5: 73.98 | H5: =F5*G5 -> 55485 | I5: ='Google Data'!C4 -> 100.59 | J5: =F5*I5 -> 75442.5 | K5: =J5/$J$13 -> 0.38355067 | L5: =J5-H5 -> 19957.5 | M5: =L5/H5 -> 0.35969181 | N5: ='Google Data'!D4*'Stocks Dashboard'!F5 -> 5377.5 | O5: ='Google Data'!C4/('Google Data'!C4-'Google Data'!D4)-1 -> 0.076750161
B6: ='Google Data'!A5 -> STEM | C6: ='Google Data'!B5 -> Stem Inc | D6: Renewable Energy | E6: =IF('Google Data'!G5>10,"Large",IF('Google Data'!G5>2,"Mid","Small")) -> Small | F6: 2000 | G6: 11.25 | H6: =F6*G6 -> 22500 | I6: ='Google Data'!C5 -> 3.54 | J6: =F6*I6 -> 7080 | K6: =J6/$J$13 -> 0.035994814 | L6: =J6-H6 -> -15420 | M6: =L6/H6 -> -0.68533333 | N6: ='Google Data'!D5*'Stocks Dashboard'!F6 -> 260 | O6: ='Google Data'!C5/('Google Data'!C5-'Google Data'!D5)-1 -> 0.038123167
B7: ='Google Data'!A6 -> RUN | C7: ='Google Data'!B6 -> Sunrun Inc | D7: Renewable Energy | E7: =IF('Google Data'!G6>10,"Large",IF('Google Data'!G6>2,"Mid","Small")) -> Small | F7: 750 | G7: 12.55 | H7: =F7*G7 -> 9412.5 | I7: ='Google Data'!C6 -> 7.58 | J7: =F7*I7 -> 5685 | K7: =J7/$J$13 -> 0.028902616 | L7: =J7-H7 -> -3727.5 | M7: =L7/H7 -> -0.39601594 | N7: ='Google Data'!D6*'Stocks Dashboard'!F7 -> 517.5 | O7: ='Google Data'!C6/('Google Data'!C6-'Google Data'!D6)-1 -> 0.10014514
B8: ='Google Data'!A7 -> BLDP | C8: ='Google Data'!B7 -> Ballard Power Systems Inc | D8: Renewable Energy | E8: =IF('Google Data'!G7>10,"Large",IF('Google Data'!G7>2,"Mid","Small")) -> Small | F8: 2000 | G8: 2.46 | H8: =F8*G8 -> 4920 | I8: ='Google Data'!C7 -> 1.53 | J8: =F8*I8 -> 3060 | K8: =J8/$J$13 -> 0.015557081 | L8: =J8-H8 -> -1860 | M8: =L8/H8 -> -0.37804878 | N8: ='Google Data'!D7*'Stocks Dashboard'!F8 -> 20 | O8: ='Google Data'!C7/('Google Data'!C7-'Google Data'!D7)-1 -> 0.0065789474
B9: ='Google Data'!A8 -> EVGO | C9: ='Google Data'!B8 -> Evgo Inc | D9: Utilities | E9: =IF('Google Data'!G8>10,"Large",IF('Google Data'!G8>2,"Mid","Small")) -> Small | F9: 2000 | G9: 1.21 | H9: =F9*G9 -> 2420 | I9: ='Google Data'!C8 -> 1.1 | J9: =F9*I9 -> 2200 | K9: =J9/$J$13 -> 0.011184829 | L9: =J9-H9 -> -220 | M9: =L9/H9 -> -0.090909091 | N9: ='Google Data'!D8*'Stocks Dashboard'!F9 -> 80 | O9: ='Google Data'!C8/('Google Data'!C8-'Google Data'!D8)-1 -> 0.037735849
B10: ='Google Data'!A9 -> COUR | C10: ='Google Data'!B9 -> Coursera Inc | D10: Technology | E10: =IF('Google Data'!G9>10,"Large",IF('Google Data'!G9>2,"Mid","Small")) -> Small | F10: 2000 | G10: 5.93 | H10: =F10*G10 -> 11860 | I10: ='Google Data'!C9 -> 5.08 | J10: =F10*I10 -> 10160 | K10: =J10/$J$13 -> 0.051653575 | L10: =J10-H10 -> -1700 | M10: =L10/H10 -> -0.14333895 | N10: ='Google Data'!D9*'Stocks Dashboard'!F10 -> 140 | O10: ='Google Data'!C9/('Google Data'!C9-'Google Data'!D9)-1 -> 0.013972056
B11: ='Google Data'!A10 -> NNOX | C11: ='Google Data'!B10 -> Nano-X Imaging Ltd | D11: Healthcare | E11: =IF('Google Data'!G10>10,"Large",IF('Google Data'!G10>2,"Mid","Small")) -> Small | F11: 2000 | G11: 2.39 | H11: =F11*G11 -> 4780 | I11: ='Google Data'!C10 -> 0.43 | J11: =F11*I11 -> 860 | K11: =J11/$J$13 -> 0.0043722515 | L11: =J11-H11 -> -3920 | M11: =L11/H11 -> -0.82008368 | N11: ='Google Data'!D10*'Stocks Dashboard'!F11 -> 40 | O11: ='Google Data'!C10/('Google Data'!C10-'Google Data'!D10)-1 -> 0.048780488
B12: ='Google Data'!A11 -> FSLY | C12: ='Google Data'!B11 -> Fastly Inc | D12: Technology | E12: =IF('Google Data'!G11>10,"Large",IF('Google Data'!G11>2,"Mid","Small")) -> Mid | F12: 750 | G12: 25.58 | H12: =F12*G12 -> 19185 | I12: ='Google Data'!C11 -> 22.12 | J12: =F12*I12 -> 16590 | K12: =J12/$J$13 -> 0.084343781 | L12: =J12-H12 -> -2595 | M12: =L12/H12 -> -0.13526192 | N12: ='Google Data'!D11*'Stocks Dashboard'!F12 -> -652.5 | O12: ='Google Data'!C11/('Google Data'!C11-'Google Data'!D11)-1 -> -0.03784254
B13: Total | H13: =SUM(H3:H12) -> 190900 | J13: =SUM(J3:J12) -> 196695 | L13: =SUM(L3:L12) -> 5795 | N13: =SUM(N3:N12) -> 5632.5

Sheet Helper
B2: Cap Size | C2: Allocation | H2: Sector | I2: Allocation
B3: Small | C3: =SUMIF('Stocks Dashboard'!$E$3:$E$12,Helper!B3,'Stocks Dashboard'!$K$3:$K$12) -> 0.14766517 | H3: Technology | I3: =SUMIF('Stocks Dashboard'!$D$3:$D$12,Helper!H3,'Stocks Dashboard'!$K$3:$K$12) -> 0.79526678
B4: Mid | C4: =SUMIF('Stocks Dashboard'!$E$3:$E$12,Helper!B4,'Stocks Dashboard'!$K$3:$K$12) -> 0.46789446 | H4: Healthcare | I4: =SUMIF('Stocks Dashboard'!$D$3:$D$12,Helper!H4,'Stocks Dashboard'!$K$3:$K$12) -> 0.11309388
B5: Large | C5: =SUMIF('Stocks Dashboard'!$E$3:$E$12,Helper!B5,'Stocks Dashboard'!$K$3:$K$12) -> 0.38444038 | H5: Renewable Energy | I5: =SUMIF('Stocks Dashboard'!$D$3:$D$12,Helper!H5,'Stocks Dashboard'!$K$3:$K$12) -> 0.080454511
C6: =SUM(C3:C5) -> 1 | H6: Utilities | I6: =SUMIF('Stocks Dashboard'!$D$3:$D$12,Helper!H6,'Stocks Dashboard'!$K$3:$K$12) -> 0.011184829
I7: =SUM(I3:I6) -> 1

Sheet NVDA
A1: Ticker Name | B1: Company | C1: Date | D1: Open | E1: Close | F1: % Change | G1: Notes
A2: NVDA | B2: NVIDIA Corporation | C2: 46098 | D2: 185.06 | E2: 181.93 | F2: =IF(OR(D2=0,NOT(ISNUMBER(D2)),NOT(ISNUMBER(E2))),"",(E2 - D2) / D2) -> -0.016913433 | G2: GTC keynote day; Vera Rubin unveiled
A3: NVDA | B3: NVIDIA Corporation | C3: 46099 | D3: 182.48 | E3: 180.4 | F3: =IF(OR(D3=0,NOT(ISNUMBER(D3)),NOT(ISNUMBER(E3))),"",(E3 - D3) / D3) -> -0.011398509 | G3: FOMC decision day
A4: NVDA | B4: NVIDIA Corporation | C4: 46100 | D4: 178.01 | E4: 178.56 | F4: =IF(OR(D4=0,NOT(ISNUMBER(D4)),NOT(ISNUMBER(E4))),"",(E4 - D4) / D4) -> 0.0030897141
A5: NVDA | B5: NVIDIA Corporation | C5: 46101 | D5: 178 | E5: 172.7 | F5: =IF(OR(D5=0,NOT(ISNUMBER(D5)),NOT(ISNUMBER(E5))),"",(E5 - D5) / D5) -> -0.029775281 | G5: Quad witching selloff
A6: NVDA | B6: NVIDIA Corporation | C6: 46105 | D6: 174.83 | E6: 175.2 | F6: =IF(OR(D6=0,NOT(ISNUMBER(D6)),NOT(ISNUMBER(E6))),"",(E6 - D6) / D6) -> 0.0021163416 | G6: Bounce from $172.70
A7: NVDA | B7: NVIDIA Corporation | C7: 46106 | D7: 177.1 | E7: 178.68 | F7: =IF(OR(D7=0,NOT(ISNUMBER(D7)),NOT(ISNUMBER(E7))),"",(E7 - D7) / D7) -> 0.0089215133
A8: NVDA | B8: NVIDIA Corporation | C8: 46107 | D8: 176.07 | E8: 171.24 | F8: =IF(OR(D8=0,NOT(ISNUMBER(D8)),NOT(ISNUMBER(E8))),"",(E8 - D8) / D8) -> -0.027432271 | G8: Sharp reversal
A9: NVDA | B9: NVIDIA Corporation | C9: 46108 | D9: 170 | E9: 167.52 | F9: =IF(OR(D9=0,NOT(ISNUMBER(D9)),NOT(ISNUMBER(E9))),"",(E9 - D9) / D9) -> -0.014588235 | G9: Near period low
A10: NVDA | B10: NVIDIA Corporation | C10: 46112 | D10: 168.78 | E10: 165.17 | F10: =IF(OR(D10=0,NOT(ISNUMBER(D10)),NOT(ISNUMBER(E10))),"",(E10 - D10) / D10) -> -0.02138879 | G10: Period Low
A11: NVDA | B11: NVIDIA Corporation | C11: 46113 | D11: 166.97 | E11: 174.4 | F11: =IF(OR(D11=0,NOT(ISNUMBER(D11)),NOT(ISNUMBER(E11))),"",(E11 - D11) / D11) -> 0.044499012 | G11: Strong bounce
A12: NVDA | B12: NVIDIA Corporation | C12: 46114 | D12: 176 | E12: 175.75 | F12: =IF(OR(D12=0,NOT(ISNUMBER(D12)),NOT(ISNUMBER(E12))),"",(E12 - D12) / D12) -> -0.0014204545
A13: NVDA | B13: NVIDIA Corporation | C13: 46115 | D13: 172.18 | E13: 177.39 | F13: =IF(OR(D13=0,NOT(ISNUMBER(D13)),NOT(ISNUMBER(E13))),"",(E13 - D13) / D13) -> 0.030259031
A14: NVDA | B14: NVIDIA Corporation | C14: 46119 | D14: 177.16 | E14: 177.64 | F14: =IF(OR(D14=0,NOT(ISNUMBER(D14)),NOT(ISNUMBER(E14))),"",(E14 - D14) / D14) -> 0.0027094152
A15: NVDA | B15: NVIDIA Corporation | C15: 46120 | D15: 175.73 | E15: 178.1 | F15: =IF(OR(D15=0,NOT(ISNUMBER(D15)),NOT(ISNUMBER(E15))),"",(E15 - D15) / D15) -> 0.013486599
A16: NVDA | B16: NVIDIA Corporation | C16: 46121 | D16: 184.5 | E16: 182.08 | F16: =IF(OR(D16=0,NOT(ISNUMBER(D16)),NOT(ISNUMBER(E16))),"",(E16 - D16) / D16) -> -0.013116531 | G16: Gap-up on ceasefire; opened +$6.40 above prior close
A17: NVDA | B17: NVIDIA Corporation | C17: 46122 | D17: 181.84 | E17: 183.91 | F17: =IF(OR(D17=0,NOT(ISNUMBER(D17)),NOT(ISNUMBER(E17))),"",(E17 - D17) / D17) -> 0.011383634
A18: NVDA | B18: NVIDIA Corporation | C18: 46123 | D18: 184.31 | E18: 188.63 | F18: =IF(OR(D18=0,NOT(ISNUMBER(D18)),NOT(ISNUMBER(E18))),"",(E18 - D18) / D18) -> 0.023438772 | G18: CPI day; AI resilience
A19: NVDA | B19: NVIDIA Corporation | C19: 46126 | D19: 186.03 | E19: 189.31 | F19: =IF(OR(D19=0,NOT(ISNUMBER(D19)),NOT(ISNUMBER(E19))),"",(E19 - D19) / D19) -> 0.017631565
A20: NVDA | B20: NVIDIA Corporation | C20: 46127 | D20: 190.84 | E20: 196.51 | F20: =IF(OR(D20=0,NOT(ISNUMBER(D20)),NOT(ISNUMBER(E20))),"",(E20 - D20) / D20) -> 0.029710752 | G20: Strong rally continues
A21: NVDA | B21: NVIDIA Corporation | C21: 46128 | D21: 196.54 | E21: 198.87 | F21: =IF(OR(D21=0,NOT(ISNUMBER(D21)),NOT(ISNUMBER(E21))),"",(E21 - D21) / D21) -> 0.011855093 | G21: Period High & Close
C24: Period Start: | D24: End: | E24: Pct Change | F24: Low: $165.17 (Mar 31) • High: $198.87 (Apr 16)
C25: 185.06 | D25: 198.87 | E25: =IF(OR(C25=0,NOT(ISNUMBER(C25)),NOT(ISNUMBER(D25))),"",(D25 - C25) / C25) -> 0.074624446

Sheet DXCM
A1: Ticker Name | B1: Company | C1: Date | D1: Open | E1: Close | F1: % Change | G1: Notes
A2: DXCM | B2: DexCom Inc. | C2: 46098 | D2: 67.11 | E2: 67.32 | F2: =IF(OR(D2=0,NOT(ISNUMBER(D2)),NOT(ISNUMBER(E2))),"",(E2 - D2) / D2) -> 0.0031291909
A3: DXCM | B3: DexCom Inc. | C3: 46099 | D3: 66.72 | E3: 67.66 | F3: =IF(OR(D3=0,NOT(ISNUMBER(D3)),NOT(ISNUMBER(E3))),"",(E3 - D3) / D3) -> 0.014088729
A4: DXCM | B4: DexCom Inc. | C4: 46100 | D4: 67.98 | E4: 67.27 | F4: =IF(OR(D4=0,NOT(ISNUMBER(D4)),NOT(ISNUMBER(E4))),"",(E4 - D4) / D4) -> -0.010444248
A5: DXCM | B5: DexCom Inc. | C5: 46101 | D5: 67.42 | E5: 66.95 | F5: =IF(OR(D5=0,NOT(ISNUMBER(D5)),NOT(ISNUMBER(E5))),"",(E5 - D5) / D5) -> -0.0069712252
A6: DXCM | B6: DexCom Inc. | C6: 46105 | D6: 66.31 | E6: 66.6 | F6: =IF(OR(D6=0,NOT(ISNUMBER(D6)),NOT(ISNUMBER(E6))),"",(E6 - D6) / D6) -> 0.0043733977
A7: DXCM | B7: DexCom Inc. | C7: 46106 | D7: 67.22 | E7: 66.84 | F7: =IF(OR(D7=0,NOT(ISNUMBER(D7)),NOT(ISNUMBER(E7))),"",(E7 - D7) / D7) -> -0.0056530794
A8: DXCM | B8: DexCom Inc. | C8: 46107 | D8: 66.84 | E8: 66.09 | F8: =IF(OR(D8=0,NOT(ISNUMBER(D8)),NOT(ISNUMBER(E8))),"",(E8 - D8) / D8) -> -0.011220826
A9: DXCM | B9: DexCom Inc. | C9: 46108 | D9: 65.91 | E9: 62.25 | F9: =IF(OR(D9=0,NOT(ISNUMBER(D9)),NOT(ISNUMBER(E9))),"",(E9 - D9) / D9) -> -0.055530269 | G9: Sharp selloff; broad market weakness
A10: DXCM | B10: DexCom Inc. | C10: 46112 | D10: 62.35 | E10: 61.9 | F10: =IF(OR(D10=0,NOT(ISNUMBER(D10)),NOT(ISNUMBER(E10))),"",(E10 - D10) / D10) -> -0.0072173216
A11: DXCM | B11: DexCom Inc. | C11: 46113 | D11: 62.77 | E11: 62.8 | F11: =IF(OR(D11=0,NOT(ISNUMBER(D11)),NOT(ISNUMBER(E11))),"",(E11 - D11) / D11) -> 0.00047793532 | G11: Bounce
A12: DXCM | B12: DexCom Inc. | C12: 46114 | D12: 62.8 | E12: 62.37 | F12: =IF(OR(D12=0,NOT(ISNUMBER(D12)),NOT(ISNUMBER(E12))),"",(E12 - D12) / D12) -> -0.0068471338
A13: DXCM | B13: DexCom Inc. | C13: 46115 | D13: 61.6 | E13: 62.22 | F13: =IF(OR(D13=0,NOT(ISNUMBER(D13)),NOT(ISNUMBER(E13))),"",(E13 - D13) / D13) -> 0.010064935
A14: DXCM | B14: DexCom Inc. | C14: 46119 | D14: 62.22 | E14: 63.21 | F14: =IF(OR(D14=0,NOT(ISNUMBER(D14)),NOT(ISNUMBER(E14))),"",(E14 - D14) / D14) -> 0.015911283
A15: DXCM | B15: DexCom Inc. | C15: 46120 | D15: 63.1 | E15: 63.11 | F15: =IF(OR(D15=0,NOT(ISNUMBER(D15)),NOT(ISNUMBER(E15))),"",(E15 - D15) / D15) -> 0.00015847861
A16: DXCM | B16: DexCom Inc. | C16: 46121 | D16: 65.01 | E16: 65.8 | F16: =IF(OR(D16=0,NOT(ISNUMBER(D16)),NOT(ISNUMBER(E16))),"",(E16 - D16) / D16) -> 0.012151977 | G16: Ceasefire rally; healthcare bid
A17: DXCM | B17: DexCom Inc. | C17: 46122 | D17: 65.39 | E17: 65.68 | F17: =IF(OR(D17=0,NOT(ISNUMBER(D17)),NOT(ISNUMBER(E17))),"",(E17 - D17) / D17) -> 0.0044349289
A18: DXCM | B18: DexCom Inc. | C18: 46123 | D18: 65.9 | E18: 64.02 | F18: =IF(OR(D18=0,NOT(ISNUMBER(D18)),NOT(ISNUMBER(E18))),"",(E18 - D18) / D18) -> -0.028528073 | G18: Hot CPI weighs on growth names
A19: DXCM | B19: DexCom Inc. | C19: 46126 | D19: 63.99 | E19: 63.12 | F19: =IF(OR(D19=0,NOT(ISNUMBER(D19)),NOT(ISNUMBER(E19))),"",(E19 - D19) / D19) -> -0.013595874
A20: DXCM | B20: DexCom Inc. | C20: 46127 | D20: 62.69 | E20: 62.95 | F20: =IF(OR(D20=0,NOT(ISNUMBER(D20)),NOT(ISNUMBER(E20))),"",(E20 - D20) / D20) -> 0.0041473919
A21: DXCM | B21: DexCom Inc. | C21: 46128 | D21: 63.04 | E21: 61.54 | F21: =IF(OR(D21=0,NOT(ISNUMBER(D21)),NOT(ISNUMBER(E21))),"",(E21 - D21) / D21) -> -0.023794416 | G21: Near Period Low
C24: Period Start: | D24: End: | E24: Pct Change | F24: Low: $61.54 (Apr 16) • High: $67.66 (Mar 18)
C25: 67.11 | D25: 61.54 | E25: =IF(OR(C25=0,NOT(ISNUMBER(C25)),NOT(ISNUMBER(D25))),"",(D25 - C25) / C25) -> -0.082998063

Sheet MNDY
A1: Ticker Name | B1: Company | C1: Date | D1: Open | E1: Close | F1: % Change | G1: Notes
A2: MNDY | B2: monday.com Ltd. | C2: 46098 | D2: 74.43 | E2: 75.28 | F2: =IF(OR(D2=0,NOT(ISNUMBER(D2)),NOT(ISNUMBER(E2))),"",(E2 - D2) / D2) -> 0.011420126
A3: MNDY | B3: monday.com Ltd. | C3: 46099 | D3: 74.24 | E3: 73.97 | F3: =IF(OR(D3=0,NOT(ISNUMBER(D3)),NOT(ISNUMBER(E3))),"",(E3 - D3) / D3) -> -0.0036368534
A4: MNDY | B4: monday.com Ltd. | C4: 46100 | D4: 73.8 | E4: 74.73 | F4: =IF(OR(D4=0,NOT(ISNUMBER(D4)),NOT(ISNUMBER(E4))),"",(E4 - D4) / D4) -> 0.012601626
A5: MNDY | B5: monday.com Ltd. | C5: 46101 | D5: 74.36 | E5: 73.85 | F5: =IF(OR(D5=0,NOT(ISNUMBER(D5)),NOT(ISNUMBER(E5))),"",(E5 - D5) / D5) -> -0.0068585261
A6: MNDY | B6: monday.com Ltd. | C6: 46105 | D6: 74.31 | E6: 72.37 | F6: =IF(OR(D6=0,NOT(ISNUMBER(D6)),NOT(ISNUMBER(E6))),"",(E6 - D6) / D6) -> -0.02610685 | G6: Agentalent.ai news fades; lawsuits gain traction
A7: MNDY | B7: monday.com Ltd. | C7: 46106 | D7: 74.79 | E7: 69.28 | F7: =IF(OR(D7=0,NOT(ISNUMBER(D7)),NOT(ISNUMBER(E7))),"",(E7 - D7) / D7) -> -0.073672951 | G7: –7.4% from open. Class action filings accelerate
A8: MNDY | B8: monday.com Ltd. | C8: 46107 | D8: 68.55 | E8: 69.38 | F8: =IF(OR(D8=0,NOT(ISNUMBER(D8)),NOT(ISNUMBER(E8))),"",(E8 - D8) / D8) -> 0.01210795 | G8: Stabilization attempt
A9: MNDY | B9: monday.com Ltd. | C9: 46108 | D9: 67.75 | E9: 66.47 | F9: =IF(OR(D9=0,NOT(ISNUMBER(D9)),NOT(ISNUMBER(E9))),"",(E9 - D9) / D9) -> -0.018892989 | G9: Continued selling
A10: MNDY | B10: monday.com Ltd. | C10: 46112 | D10: 67.01 | E10: 67.88 | F10: =IF(OR(D10=0,NOT(ISNUMBER(D10)),NOT(ISNUMBER(E10))),"",(E10 - D10) / D10) -> 0.012983137
A11: MNDY | B11: monday.com Ltd. | C11: 46113 | D11: 68.9 | E11: 69.11 | F11: =IF(OR(D11=0,NOT(ISNUMBER(D11)),NOT(ISNUMBER(E11))),"",(E11 - D11) / D11) -> 0.0030478955
A12: MNDY | B12: monday.com Ltd. | C12: 46114 | D12: 69.95 | E12: 68.1 | F12: =IF(OR(D12=0,NOT(ISNUMBER(D12)),NOT(ISNUMBER(E12))),"",(E12 - D12) / D12) -> -0.026447462
A13: MNDY | B13: monday.com Ltd. | C13: 46115 | D13: 68.1 | E13: 68.34 | F13: =IF(OR(D13=0,NOT(ISNUMBER(D13)),NOT(ISNUMBER(E13))),"",(E13 - D13) / D13) -> 0.0035242291
A14: MNDY | B14: monday.com Ltd. | C14: 46119 | D14: 68.34 | E14: 67.7 | F14: =IF(OR(D14=0,NOT(ISNUMBER(D14)),NOT(ISNUMBER(E14))),"",(E14 - D14) / D14) -> -0.00936494
A15: MNDY | B15: monday.com Ltd. | C15: 46120 | D15: 67.07 | E15: 66.71 | F15: =IF(OR(D15=0,NOT(ISNUMBER(D15)),NOT(ISNUMBER(E15))),"",(E15 - D15) / D15) -> -0.0053675265
A16: MNDY | B16: monday.com Ltd. | C16: 46121 | D16: 69.26 | E16: 65.64 | F16: =IF(OR(D16=0,NOT(ISNUMBER(D16)),NOT(ISNUMBER(E16))),"",(E16 - D16) / D16) -> -0.052266821 | G16: Selling resumes
A17: MNDY | B17: monday.com Ltd. | C17: 46122 | D17: 64.71 | E17: 62.39 | F17: =IF(OR(D17=0,NOT(ISNUMBER(D17)),NOT(ISNUMBER(E17))),"",(E17 - D17) / D17) -> -0.035852264 | G17: Breakdown accelerates
A18: MNDY | B18: monday.com Ltd. | C18: 46123 | D18: 62.5 | E18: 58.81 | F18: =IF(OR(D18=0,NOT(ISNUMBER(D18)),NOT(ISNUMBER(E18))),"",(E18 - D18) / D18) -> -0.05904 | G18: Period Low. Below $60 for first time
A19: MNDY | B19: monday.com Ltd. | C19: 46126 | D19: 58.92 | E19: 63.55 | F19: =IF(OR(D19=0,NOT(ISNUMBER(D19)),NOT(ISNUMBER(E19))),"",(E19 - D19) / D19) -> 0.078581127 | G19: Oversold bounce
A20: MNDY | B20: monday.com Ltd. | C20: 46127 | D20: 63.55 | E20: 61.69 | F20: =IF(OR(D20=0,NOT(ISNUMBER(D20)),NOT(ISNUMBER(E20))),"",(E20 - D20) / D20) -> -0.029268293 | G20: Bounce fades
A21: MNDY | B21: monday.com Ltd. | C21: 46128 | D21: 64.4 | E21: 65.43 | F21: =IF(OR(D21=0,NOT(ISNUMBER(D21)),NOT(ISNUMBER(E21))),"",(E21 - D21) / D21) -> 0.015993789 | G21: Partial recovery
C24: Period Start: | D24: End: | E24: Pct Change | F24: Low: $58.81 (Apr 11) • High: $75.28 (Mar 17). WORST PERFORMER.
C25: 74.43 | D25: 65.43 | E25: =IF(OR(C25=0,NOT(ISNUMBER(C25)),NOT(ISNUMBER(D25))),"",(D25 - C25) / C25) -> -0.12091898

Sheet STEM
A1: Ticker Name | B1: Company | C1: Date | D1: Open | E1: Close | F1: % Change | G1: Notes
A2: STEM | B2: Stem Inc. | C2: 46098 | D2: 10.94 | E2: 10.9 | F2: =IF(OR(D2=0,NOT(ISNUMBER(D2)),NOT(ISNUMBER(E2))),"",(E2 - D2) / D2) -> -0.0036563071
A3: STEM | B3: Stem Inc. | C3: 46099 | D3: 10.66 | E3: 10.59 | F3: =IF(OR(D3=0,NOT(ISNUMBER(D3)),NOT(ISNUMBER(E3))),"",(E3 - D3) / D3) -> -0.0065666041
A4: STEM | B4: Stem Inc. | C4: 46100 | D4: 10.31 | E4: 10.46 | F4: =IF(OR(D4=0,NOT(ISNUMBER(D4)),NOT(ISNUMBER(E4))),"",(E4 - D4) / D4) -> 0.014548982
A5: STEM | B5: Stem Inc. | C5: 46101 | D5: 10.42 | E5: 9.7 | F5: =IF(OR(D5=0,NOT(ISNUMBER(D5)),NOT(ISNUMBER(E5))),"",(E5 - D5) / D5) -> -0.069097889 | G5: Sharp selloff on quad witching
A6: STEM | B6: Stem Inc. | C6: 46105 | D6: 9.99 | E6: 9.99 | F6: =IF(OR(D6=0,NOT(ISNUMBER(D6)),NOT(ISNUMBER(E6))),"",(E6 - D6) / D6) -> 0
A7: STEM | B7: Stem Inc. | C7: 46106 | D7: 10.1 | E7: 10.47 | F7: =IF(OR(D7=0,NOT(ISNUMBER(D7)),NOT(ISNUMBER(E7))),"",(E7 - D7) / D7) -> 0.036633663 | G7: Bounce
A8: STEM | B8: Stem Inc. | C8: 46107 | D8: 10.22 | E8: 9.72 | F8: =IF(OR(D8=0,NOT(ISNUMBER(D8)),NOT(ISNUMBER(E8))),"",(E8 - D8) / D8) -> -0.048923679 | G8: Reversal
A9: STEM | B9: Stem Inc. | C9: 46108 | D9: 9.41 | E9: 8.75 | F9: =IF(OR(D9=0,NOT(ISNUMBER(D9)),NOT(ISNUMBER(E9))),"",(E9 - D9) / D9) -> -0.070138151 | G9: Broad selloff
A10: STEM | B10: Stem Inc. | C10: 46112 | D10: 8.79 | E10: 8.25 | F10: =IF(OR(D10=0,NOT(ISNUMBER(D10)),NOT(ISNUMBER(E10))),"",(E10 - D10) / D10) -> -0.061433447 | G10: Period Low
A11: STEM | B11: Stem Inc. | C11: 46113 | D11: 8.47 | E11: 8.84 | F11: =IF(OR(D11=0,NOT(ISNUMBER(D11)),NOT(ISNUMBER(E11))),"",(E11 - D11) / D11) -> 0.043683589 | G11: Strong bounce
A12: STEM | B12: Stem Inc. | C12: 46114 | D12: 8.94 | E12: 8.83 | F12: =IF(OR(D12=0,NOT(ISNUMBER(D12)),NOT(ISNUMBER(E12))),"",(E12 - D12) / D12) -> -0.012304251
A13: STEM | B13: Stem Inc. | C13: 46115 | D13: 8.39 | E13: 8.66 | F13: =IF(OR(D13=0,NOT(ISNUMBER(D13)),NOT(ISNUMBER(E13))),"",(E13 - D13) / D13) -> 0.032181168
A14: STEM | B14: Stem Inc. | C14: 46119 | D14: 8.67 | E14: 9.07 | F14: =IF(OR(D14=0,NOT(ISNUMBER(D14)),NOT(ISNUMBER(E14))),"",(E14 - D14) / D14) -> 0.046136101
A15: STEM | B15: Stem Inc. | C15: 46120 | D15: 8.88 | E15: 8.81 | F15: =IF(OR(D15=0,NOT(ISNUMBER(D15)),NOT(ISNUMBER(E15))),"",(E15 - D15) / D15) -> -0.0078828829
A16: STEM | B16: Stem Inc. | C16: 46121 | D16: 9.54 | E16: 9.68 | F16: =IF(OR(D16=0,NOT(ISNUMBER(D16)),NOT(ISNUMBER(E16))),"",(E16 - D16) / D16) -> 0.014675052 | G16: Ceasefire rally; energy bid
A17: STEM | B17: Stem Inc. | C17: 46122 | D17: 9.4 | E17: 9.73 | F17: =IF(OR(D17=0,NOT(ISNUMBER(D17)),NOT(ISNUMBER(E17))),"",(E17 - D17) / D17) -> 0.035106383
A18: STEM | B18: Stem Inc. | C18: 46123 | D18: 9.8 | E18: 9.42 | F18: =IF(OR(D18=0,NOT(ISNUMBER(D18)),NOT(ISNUMBER(E18))),"",(E18 - D18) / D18) -> -0.03877551 | G18: CPI pressure
A19: STEM | B19: Stem Inc. | C19: 46126 | D19: 9.25 | E19: 9.65 | F19: =IF(OR(D19=0,NOT(ISNUMBER(D19)),NOT(ISNUMBER(E19))),"",(E19 - D19) / D19) -> 0.043243243
A20: STEM | B20: Stem Inc. | C20: 46127 | D20: 10 | E20: 10.35 | F20: =IF(OR(D20=0,NOT(ISNUMBER(D20)),NOT(ISNUMBER(E20))),"",(E20 - D20) / D20) -> 0.035 | G20: Clean energy momentum
A21: STEM | B21: Stem Inc. | C21: 46128 | D21: 10.52 | E21: 10.75 | F21: =IF(OR(D21=0,NOT(ISNUMBER(D21)),NOT(ISNUMBER(E21))),"",(E21 - D21) / D21) -> 0.021863118
C24: Period Start: | D24: End: | E24: Pct Change | F24: Low: $8.25 (Mar 31) • High: $10.90 (Mar 17)
C25: 10.94 | D25: 10.75 | E25: =IF(OR(C25=0,NOT(ISNUMBER(C25)),NOT(ISNUMBER(D25))),"",(D25 - C25) / C25) -> -0.017367459

Sheet RUN
A1: Ticker Name | B1: Company | C1: Date | D1: Open | E1: Close | F1: % Change | G1: Notes
A2: RUN | B2: Sunrun Inc. | C2: 46098 | D2: 12.93 | E2: 13.29 | F2: =IF(OR(D2=0,NOT(ISNUMBER(D2)),NOT(ISNUMBER(E2))),"",(E2 - D2) / D2) -> 0.027842227
A3: RUN | B3: Sunrun Inc. | C3: 46099 | D3: 13.37 | E3: 12.79 | F3: =IF(OR(D3=0,NOT(ISNUMBER(D3)),NOT(ISNUMBER(E3))),"",(E3 - D3) / D3) -> -0.043380703 | G3: FOMC reaction
A4: RUN | B4: Sunrun Inc. | C4: 46100 | D4: 12.52 | E4: 13.08 | F4: =IF(OR(D4=0,NOT(ISNUMBER(D4)),NOT(ISNUMBER(E4))),"",(E4 - D4) / D4) -> 0.044728435
A5: RUN | B5: Sunrun Inc. | C5: 46101 | D5: 13.05 | E5: 12.22 | F5: =IF(OR(D5=0,NOT(ISNUMBER(D5)),NOT(ISNUMBER(E5))),"",(E5 - D5) / D5) -> -0.063601533 | G5: Sharp selloff
A6: RUN | B6: Sunrun Inc. | C6: 46105 | D6: 12.42 | E6: 12.75 | F6: =IF(OR(D6=0,NOT(ISNUMBER(D6)),NOT(ISNUMBER(E6))),"",(E6 - D6) / D6) -> 0.026570048
A7: RUN | B7: Sunrun Inc. | C7: 46106 | D7: 12.95 | E7: 13.04 | F7: =IF(OR(D7=0,NOT(ISNUMBER(D7)),NOT(ISNUMBER(E7))),"",(E7 - D7) / D7) -> 0.0069498069
A8: RUN | B8: Sunrun Inc. | C8: 46107 | D8: 12.74 | E8: 12.4 | F8: =IF(OR(D8=0,NOT(ISNUMBER(D8)),NOT(ISNUMBER(E8))),"",(E8 - D8) / D8) -> -0.026687598
A9: RUN | B9: Sunrun Inc. | C9: 46108 | D9: 12.19 | E9: 12.6 | F9: =IF(OR(D9=0,NOT(ISNUMBER(D9)),NOT(ISNUMBER(E9))),"",(E9 - D9) / D9) -> 0.033634126
A10: RUN | B10: Sunrun Inc. | C10: 46112 | D10: 12.89 | E10: 12.14 | F10: =IF(OR(D10=0,NOT(ISNUMBER(D10)),NOT(ISNUMBER(E10))),"",(E10 - D10) / D10) -> -0.058184639
A11: RUN | B11: Sunrun Inc. | C11: 46113 | D11: 12.53 | E11: 13.56 | F11: =IF(OR(D11=0,NOT(ISNUMBER(D11)),NOT(ISNUMBER(E11))),"",(E11 - D11) / D11) -> 0.082202713 | G11: Strong bounce
A12: RUN | B12: Sunrun Inc. | C12: 46114 | D12: 13.8 | E12: 14.15 | F12: =IF(OR(D12=0,NOT(ISNUMBER(D12)),NOT(ISNUMBER(E12))),"",(E12 - D12) / D12) -> 0.025362319 | G12: Period High
A13: RUN | B13: Sunrun Inc. | C13: 46115 | D13: 13.63 | E13: 13.5 | F13: =IF(OR(D13=0,NOT(ISNUMBER(D13)),NOT(ISNUMBER(E13))),"",(E13 - D13) / D13) -> -0.0095377843
A14: RUN | B14: Sunrun Inc. | C14: 46119 | D14: 13.42 | E14: 13.23 | F14: =IF(OR(D14=0,NOT(ISNUMBER(D14)),NOT(ISNUMBER(E14))),"",(E14 - D14) / D14) -> -0.014157973
A15: RUN | B15: Sunrun Inc. | C15: 46120 | D15: 13.05 | E15: 13.22 | F15: =IF(OR(D15=0,NOT(ISNUMBER(D15)),NOT(ISNUMBER(E15))),"",(E15 - D15) / D15) -> 0.01302682
A16: RUN | B16: Sunrun Inc. | C16: 46121 | D16: 14.34 | E16: 13.87 | F16: =IF(OR(D16=0,NOT(ISNUMBER(D16)),NOT(ISNUMBER(E16))),"",(E16 - D16) / D16) -> -0.032775453 | G16: Ceasefire rally
A17: RUN | B17: Sunrun Inc. | C17: 46122 | D17: 13.7 | E17: 13.33 | F17: =IF(OR(D17=0,NOT(ISNUMBER(D17)),NOT(ISNUMBER(E17))),"",(E17 - D17) / D17) -> -0.027007299
A18: RUN | B18: Sunrun Inc. | C18: 46123 | D18: 13.4 | E18: 13.28 | F18: =IF(OR(D18=0,NOT(ISNUMBER(D18)),NOT(ISNUMBER(E18))),"",(E18 - D18) / D18) -> -0.0089552239
A19: RUN | B19: Sunrun Inc. | C19: 46126 | D19: 13.09 | E19: 12.76 | F19: =IF(OR(D19=0,NOT(ISNUMBER(D19)),NOT(ISNUMBER(E19))),"",(E19 - D19) / D19) -> -0.025210084
A20: RUN | B20: Sunrun Inc. | C20: 46127 | D20: 13.05 | E20: 12.45 | F20: =IF(OR(D20=0,NOT(ISNUMBER(D20)),NOT(ISNUMBER(E20))),"",(E20 - D20) / D20) -> -0.045977011
A21: RUN | B21: Sunrun Inc. | C21: 46128 | D21: 12.59 | E21: 12.1 | F21: =IF(OR(D21=0,NOT(ISNUMBER(D21)),NOT(ISNUMBER(E21))),"",(E21 - D21) / D21) -> -0.038919778 | G21: Continued fade
C24: Period Start: | D24: End: | E24: Pct Change | F24: Low: $12.10 (Apr 16) • High: $14.15 (Apr 2)
C25: 12.93 | D25: 12.1 | E25: =IF(OR(C25=0,NOT(ISNUMBER(C25)),NOT(ISNUMBER(D25))),"",(D25 - C25) / C25) -> -0.064191802

Sheet BLDP
A1: Ticker Name | B1: Company | C1: Date | D1: Open | E1: Close | F1: % Change | G1: Notes
A2: BLDP | B2: Ballard Power Systems Inc. | C2: 46098 | D2: 2.56 | E2: 2.68 | F2: =IF(OR(D2=0,NOT(ISNUMBER(D2)),NOT(ISNUMBER(E2))),"",(E2 - D2) / D2) -> 0.046875 | G2: Strong open to period
A3: BLDP | B3: Ballard Power Systems Inc. | C3: 46099 | D3: 2.64 | E3: 2.61 | F3: =IF(OR(D3=0,NOT(ISNUMBER(D3)),NOT(ISNUMBER(E3))),"",(E3 - D3) / D3) -> -0.011363636
A4: BLDP | B4: Ballard Power Systems Inc. | C4: 46100 | D4: 2.51 | E4: 2.48 | F4: =IF(OR(D4=0,NOT(ISNUMBER(D4)),NOT(ISNUMBER(E4))),"",(E4 - D4) / D4) -> -0.011952191
A5: BLDP | B5: Ballard Power Systems Inc. | C5: 46101 | D5: 2.47 | E5: 2.41 | F5: =IF(OR(D5=0,NOT(ISNUMBER(D5)),NOT(ISNUMBER(E5))),"",(E5 - D5) / D5) -> -0.024291498
A6: BLDP | B6: Ballard Power Systems Inc. | C6: 46105 | D6: 2.47 | E6: 2.46 | F6: =IF(OR(D6=0,NOT(ISNUMBER(D6)),NOT(ISNUMBER(E6))),"",(E6 - D6) / D6) -> -0.004048583
A7: BLDP | B7: Ballard Power Systems Inc. | C7: 46106 | D7: 2.5 | E7: 2.54 | F7: =IF(OR(D7=0,NOT(ISNUMBER(D7)),NOT(ISNUMBER(E7))),"",(E7 - D7) / D7) -> 0.016
A8: BLDP | B8: Ballard Power Systems Inc. | C8: 46107 | D8: 2.49 | E8: 2.45 | F8: =IF(OR(D8=0,NOT(ISNUMBER(D8)),NOT(ISNUMBER(E8))),"",(E8 - D8) / D8) -> -0.016064257
A9: BLDP | B9: Ballard Power Systems Inc. | C9: 46108 | D9: 2.41 | E9: 2.39 | F9: =IF(OR(D9=0,NOT(ISNUMBER(D9)),NOT(ISNUMBER(E9))),"",(E9 - D9) / D9) -> -0.0082987552
A10: BLDP | B10: Ballard Power Systems Inc. | C10: 46112 | D10: 2.42 | E10: 2.3 | F10: =IF(OR(D10=0,NOT(ISNUMBER(D10)),NOT(ISNUMBER(E10))),"",(E10 - D10) / D10) -> -0.049586777 | G10: Near Period Low
A11: BLDP | B11: Ballard Power Systems Inc. | C11: 46113 | D11: 2.32 | E11: 2.42 | F11: =IF(OR(D11=0,NOT(ISNUMBER(D11)),NOT(ISNUMBER(E11))),"",(E11 - D11) / D11) -> 0.043103448 | G11: Bounce
A12: BLDP | B12: Ballard Power Systems Inc. | C12: 46114 | D12: 2.44 | E12: 2.41 | F12: =IF(OR(D12=0,NOT(ISNUMBER(D12)),NOT(ISNUMBER(E12))),"",(E12 - D12) / D12) -> -0.012295082
A13: BLDP | B13: Ballard Power Systems Inc. | C13: 46115 | D13: 2.35 | E13: 2.48 | F13: =IF(OR(D13=0,NOT(ISNUMBER(D13)),NOT(ISNUMBER(E13))),"",(E13 - D13) / D13) -> 0.055319149
A14: BLDP | B14: Ballard Power Systems Inc. | C14: 46119 | D14: 2.5 | E14: 2.53 | F14: =IF(OR(D14=0,NOT(ISNUMBER(D14)),NOT(ISNUMBER(E14))),"",(E14 - D14) / D14) -> 0.012
A15: BLDP | B15: Ballard Power Systems Inc. | C15: 46120 | D15: 2.51 | E15: 2.4 | F15: =IF(OR(D15=0,NOT(ISNUMBER(D15)),NOT(ISNUMBER(E15))),"",(E15 - D15) / D15) -> -0.043824701
A16: BLDP | B16: Ballard Power Systems Inc. | C16: 46121 | D16: 2.55 | E16: 2.6 | F16: =IF(OR(D16=0,NOT(ISNUMBER(D16)),NOT(ISNUMBER(E16))),"",(E16 - D16) / D16) -> 0.019607843 | G16: Ceasefire boost; hydrogen momentum
A17: BLDP | B17: Ballard Power Systems Inc. | C17: 46122 | D17: 2.58 | E17: 2.64 | F17: =IF(OR(D17=0,NOT(ISNUMBER(D17)),NOT(ISNUMBER(E17))),"",(E17 - D17) / D17) -> 0.023255814
A18: BLDP | B18: Ballard Power Systems Inc. | C18: 46123 | D18: 2.67 | E18: 2.81 | F18: =IF(OR(D18=0,NOT(ISNUMBER(D18)),NOT(ISNUMBER(E18))),"",(E18 - D18) / D18) -> 0.052434457 | G18: Strong acceleration
A19: BLDP | B19: Ballard Power Systems Inc. | C19: 46126 | D19: 2.78 | E19: 2.7 | F19: =IF(OR(D19=0,NOT(ISNUMBER(D19)),NOT(ISNUMBER(E19))),"",(E19 - D19) / D19) -> -0.028776978 | G19: Pullback
A20: BLDP | B20: Ballard Power Systems Inc. | C20: 46127 | D20: 2.81 | E20: 2.86 | F20: =IF(OR(D20=0,NOT(ISNUMBER(D20)),NOT(ISNUMBER(E20))),"",(E20 - D20) / D20) -> 0.017793594 | G20: Resumes rally
A21: BLDP | B21: Ballard Power Systems Inc. | C21: 46128 | D21: 2.98 | E21: 3.07 | F21: =IF(OR(D21=0,NOT(ISNUMBER(D21)),NOT(ISNUMBER(E21))),"",(E21 - D21) / D21) -> 0.030201342 | G21: Period High. BEST PERFORMER.
C24: Period Start: | D24: End: | E24: Pct Change | F24: Low: $2.30 (Mar 31) • High: $3.07 (Apr 16). BEST PERFORMER.
C25: 2.56 | D25: 3.07 | E25: =IF(OR(C25=0,NOT(ISNUMBER(C25)),NOT(ISNUMBER(D25))),"",(D25 - C25) / C25) -> 0.19921875

Sheet EVGO
A1: Ticker Name | B1: Company | C1: Date | D1: Open | E1: Close | F1: % Change | G1: Notes
A2: EVGO | B2: EVgo Inc. | C2: 46098 | D2: 2.11 | E2: 2.06 | F2: =IF(OR(D2=0,NOT(ISNUMBER(D2)),NOT(ISNUMBER(E2))),"",(E2 - D2) / D2) -> -0.023696682
A3: EVGO | B3: EVgo Inc. | C3: 46099 | D3: 2.05 | E3: 1.93 | F3: =IF(OR(D3=0,NOT(ISNUMBER(D3)),NOT(ISNUMBER(E3))),"",(E3 - D3) / D3) -> -0.058536585 | G3: FOMC selloff
A4: EVGO | B4: EVgo Inc. | C4: 46100 | D4: 1.9 | E4: 2.05 | F4: =IF(OR(D4=0,NOT(ISNUMBER(D4)),NOT(ISNUMBER(E4))),"",(E4 - D4) / D4) -> 0.078947368 | G4: Bounce
A5: EVGO | B5: EVgo Inc. | C5: 46101 | D5: 2.05 | E5: 1.94 | F5: =IF(OR(D5=0,NOT(ISNUMBER(D5)),NOT(ISNUMBER(E5))),"",(E5 - D5) / D5) -> -0.053658537
A6: EVGO | B6: EVgo Inc. | C6: 46105 | D6: 1.93 | E6: 1.87 | F6: =IF(OR(D6=0,NOT(ISNUMBER(D6)),NOT(ISNUMBER(E6))),"",(E6 - D6) / D6) -> -0.031088083
A7: EVGO | B7: EVgo Inc. | C7: 46106 | D7: 1.85 | E7: 1.81 | F7: =IF(OR(D7=0,NOT(ISNUMBER(D7)),NOT(ISNUMBER(E7))),"",(E7 - D7) / D7) -> -0.021621622
A8: EVGO | B8: EVgo Inc. | C8: 46107 | D8: 1.77 | E8: 1.75 | F8: =IF(OR(D8=0,NOT(ISNUMBER(D8)),NOT(ISNUMBER(E8))),"",(E8 - D8) / D8) -> -0.011299435
A9: EVGO | B9: EVgo Inc. | C9: 46108 | D9: 1.72 | E9: 1.72 | F9: =IF(OR(D9=0,NOT(ISNUMBER(D9)),NOT(ISNUMBER(E9))),"",(E9 - D9) / D9) -> 0
A10: EVGO | B10: EVgo Inc. | C10: 46112 | D10: 1.73 | E10: 1.66 | F10: =IF(OR(D10=0,NOT(ISNUMBER(D10)),NOT(ISNUMBER(E10))),"",(E10 - D10) / D10) -> -0.040462428 | G10: Period Low
A11: EVGO | B11: EVgo Inc. | C11: 46113 | D11: 1.67 | E11: 1.72 | F11: =IF(OR(D11=0,NOT(ISNUMBER(D11)),NOT(ISNUMBER(E11))),"",(E11 - D11) / D11) -> 0.02994012 | G11: Bounce
A12: EVGO | B12: EVgo Inc. | C12: 46114 | D12: 1.75 | E12: 1.77 | F12: =IF(OR(D12=0,NOT(ISNUMBER(D12)),NOT(ISNUMBER(E12))),"",(E12 - D12) / D12) -> 0.011428571
A13: EVGO | B13: EVgo Inc. | C13: 46115 | D13: 1.72 | E13: 1.71 | F13: =IF(OR(D13=0,NOT(ISNUMBER(D13)),NOT(ISNUMBER(E13))),"",(E13 - D13) / D13) -> -0.0058139535
A14: EVGO | B14: EVgo Inc. | C14: 46119 | D14: 1.71 | E14: 1.85 | F14: =IF(OR(D14=0,NOT(ISNUMBER(D14)),NOT(ISNUMBER(E14))),"",(E14 - D14) / D14) -> 0.081871345 | G14: EV infrastructure headlines
A15: EVGO | B15: EVgo Inc. | C15: 46120 | D15: 1.82 | E15: 1.8 | F15: =IF(OR(D15=0,NOT(ISNUMBER(D15)),NOT(ISNUMBER(E15))),"",(E15 - D15) / D15) -> -0.010989011
A16: EVGO | B16: EVgo Inc. | C16: 46121 | D16: 1.94 | E16: 1.91 | F16: =IF(OR(D16=0,NOT(ISNUMBER(D16)),NOT(ISNUMBER(E16))),"",(E16 - D16) / D16) -> -0.015463918 | G16: Ceasefire rally
A17: EVGO | B17: EVgo Inc. | C17: 46122 | D17: 1.88 | E17: 2 | F17: =IF(OR(D17=0,NOT(ISNUMBER(D17)),NOT(ISNUMBER(E17))),"",(E17 - D17) / D17) -> 0.063829787 | G17: Back above $2
A18: EVGO | B18: EVgo Inc. | C18: 46123 | D18: 2.03 | E18: 1.94 | F18: =IF(OR(D18=0,NOT(ISNUMBER(D18)),NOT(ISNUMBER(E18))),"",(E18 - D18) / D18) -> -0.044334975
A19: EVGO | B19: EVgo Inc. | C19: 46126 | D19: 1.9 | E19: 1.93 | F19: =IF(OR(D19=0,NOT(ISNUMBER(D19)),NOT(ISNUMBER(E19))),"",(E19 - D19) / D19) -> 0.015789474
A20: EVGO | B20: EVgo Inc. | C20: 46127 | D20: 1.98 | E20: 2.05 | F20: =IF(OR(D20=0,NOT(ISNUMBER(D20)),NOT(ISNUMBER(E20))),"",(E20 - D20) / D20) -> 0.035353535
A21: EVGO | B21: EVgo Inc. | C21: 46128 | D21: 2.05 | E21: 2.06 | F21: =IF(OR(D21=0,NOT(ISNUMBER(D21)),NOT(ISNUMBER(E21))),"",(E21 - D21) / D21) -> 0.0048780488
C24: Period Start: | D24: End: | E24: Pct Change | F24: Low: $1.66 (Mar 31) • High: $2.11 (Mar 16)
C25: 2.11 | D25: 2.06 | E25: =IF(OR(C25=0,NOT(ISNUMBER(C25)),NOT(ISNUMBER(D25))),"",(D25 - C25) / C25) -> -0.023696682

Sheet COUR
A1: Ticker Name | B1: Company | C1: Date | D1: Open | E1: Close | F1: % Change | G1: Notes
A2: COUR | B2: Coursera Inc. | C2: 46098 | D2: 6.1 | E2: 6.07 | F2: =IF(OR(D2=0,NOT(ISNUMBER(D2)),NOT(ISNUMBER(E2))),"",(E2 - D2) / D2) -> -0.0049180328
A3: COUR | B3: Coursera Inc. | C3: 46099 | D3: 5.96 | E3: 5.86 | F3: =IF(OR(D3=0,NOT(ISNUMBER(D3)),NOT(ISNUMBER(E3))),"",(E3 - D3) / D3) -> -0.016778523
A4: COUR | B4: Coursera Inc. | C4: 46100 | D4: 5.81 | E4: 6.04 | F4: =IF(OR(D4=0,NOT(ISNUMBER(D4)),NOT(ISNUMBER(E4))),"",(E4 - D4) / D4) -> 0.039586919
A5: COUR | B5: Coursera Inc. | C5: 46101 | D5: 6 | E5: 5.84 | F5: =IF(OR(D5=0,NOT(ISNUMBER(D5)),NOT(ISNUMBER(E5))),"",(E5 - D5) / D5) -> -0.026666667
A6: COUR | B6: Coursera Inc. | C6: 46105 | D6: 5.87 | E6: 5.69 | F6: =IF(OR(D6=0,NOT(ISNUMBER(D6)),NOT(ISNUMBER(E6))),"",(E6 - D6) / D6) -> -0.030664395
A7: COUR | B7: Coursera Inc. | C7: 46106 | D7: 5.81 | E7: 5.87 | F7: =IF(OR(D7=0,NOT(ISNUMBER(D7)),NOT(ISNUMBER(E7))),"",(E7 - D7) / D7) -> 0.010327022
A8: COUR | B8: Coursera Inc. | C8: 46107 | D8: 5.8 | E8: 5.84 | F8: =IF(OR(D8=0,NOT(ISNUMBER(D8)),NOT(ISNUMBER(E8))),"",(E8 - D8) / D8) -> 0.0068965517
A9: COUR | B9: Coursera Inc. | C9: 46108 | D9: 5.74 | E9: 5.51 | F9: =IF(OR(D9=0,NOT(ISNUMBER(D9)),NOT(ISNUMBER(E9))),"",(E9 - D9) / D9) -> -0.040069686 | G9: Broad selloff
A10: COUR | B10: Coursera Inc. | C10: 46112 | D10: 5.59 | E10: 5.73 | F10: =IF(OR(D10=0,NOT(ISNUMBER(D10)),NOT(ISNUMBER(E10))),"",(E10 - D10) / D10) -> 0.025044723
A11: COUR | B11: Coursera Inc. | C11: 46113 | D11: 5.8 | E11: 5.82 | F11: =IF(OR(D11=0,NOT(ISNUMBER(D11)),NOT(ISNUMBER(E11))),"",(E11 - D11) / D11) -> 0.0034482759
A12: COUR | B12: Coursera Inc. | C12: 46114 | D12: 5.78 | E12: 5.85 | F12: =IF(OR(D12=0,NOT(ISNUMBER(D12)),NOT(ISNUMBER(E12))),"",(E12 - D12) / D12) -> 0.012110727
A13: COUR | B13: Coursera Inc. | C13: 46115 | D13: 5.75 | E13: 5.91 | F13: =IF(OR(D13=0,NOT(ISNUMBER(D13)),NOT(ISNUMBER(E13))),"",(E13 - D13) / D13) -> 0.027826087
A14: COUR | B14: Coursera Inc. | C14: 46119 | D14: 5.85 | E14: 6.01 | F14: =IF(OR(D14=0,NOT(ISNUMBER(D14)),NOT(ISNUMBER(E14))),"",(E14 - D14) / D14) -> 0.027350427
A15: COUR | B15: Coursera Inc. | C15: 46120 | D15: 6 | E15: 6.04 | F15: =IF(OR(D15=0,NOT(ISNUMBER(D15)),NOT(ISNUMBER(E15))),"",(E15 - D15) / D15) -> 0.0066666667
A16: COUR | B16: Coursera Inc. | C16: 46121 | D16: 6.3 | E16: 5.53 | F16: =IF(OR(D16=0,NOT(ISNUMBER(D16)),NOT(ISNUMBER(E16))),"",(E16 - D16) / D16) -> -0.12222222 | G16: –8.5% intraday drop. Possible downgrade
A17: COUR | B17: Coursera Inc. | C17: 46122 | D17: 5.61 | E17: 5.6 | F17: =IF(OR(D17=0,NOT(ISNUMBER(D17)),NOT(ISNUMBER(E17))),"",(E17 - D17) / D17) -> -0.0017825312
A18: COUR | B18: Coursera Inc. | C18: 46123 | D18: 5.61 | E18: 5.36 | F18: =IF(OR(D18=0,NOT(ISNUMBER(D18)),NOT(ISNUMBER(E18))),"",(E18 - D18) / D18) -> -0.04456328 | G18: Near Period Low
A19: COUR | B19: Coursera Inc. | C19: 46126 | D19: 5.34 | E19: 5.75 | F19: =IF(OR(D19=0,NOT(ISNUMBER(D19)),NOT(ISNUMBER(E19))),"",(E19 - D19) / D19) -> 0.076779026 | G19: Recovery bounce
A20: COUR | B20: Coursera Inc. | C20: 46127 | D20: 5.74 | E20: 5.94 | F20: =IF(OR(D20=0,NOT(ISNUMBER(D20)),NOT(ISNUMBER(E20))),"",(E20 - D20) / D20) -> 0.034843206
A21: COUR | B21: Coursera Inc. | C21: 46128 | D21: 6.03 | E21: 6.15 | F21: =IF(OR(D21=0,NOT(ISNUMBER(D21)),NOT(ISNUMBER(E21))),"",(E21 - D21) / D21) -> 0.019900498 | G21: Full recovery
C24: Period Start: | D24: End: | E24: Pct Change | F24: Low: $5.36 (Apr 11) • High: $6.15 (Apr 16)
C25: 6.1 | D25: 6.15 | E25: =IF(OR(C25=0,NOT(ISNUMBER(C25)),NOT(ISNUMBER(D25))),"",(D25 - C25) / C25) -> 0.0081967213

Sheet NNOX
A1: Ticker Name | B1: Company | C1: Date | D1: Open | E1: Close | F1: % Change | G1: Notes
A2: NNOX | B2: Nano-X Imaging Ltd. | C2: 46098 | D2: 2.57 | E2: 2.6 | F2: =IF(OR(D2=0,NOT(ISNUMBER(D2)),NOT(ISNUMBER(E2))),"",(E2 - D2) / D2) -> 0.011673152
A3: NNOX | B3: Nano-X Imaging Ltd. | C3: 46099 | D3: 2.56 | E3: 2.46 | F3: =IF(OR(D3=0,NOT(ISNUMBER(D3)),NOT(ISNUMBER(E3))),"",(E3 - D3) / D3) -> -0.0390625
A4: NNOX | B4: Nano-X Imaging Ltd. | C4: 46100 | D4: 2.42 | E4: 2.51 | F4: =IF(OR(D4=0,NOT(ISNUMBER(D4)),NOT(ISNUMBER(E4))),"",(E4 - D4) / D4) -> 0.037190083
A5: NNOX | B5: Nano-X Imaging Ltd. | C5: 46101 | D5: 2.5 | E5: 2.41 | F5: =IF(OR(D5=0,NOT(ISNUMBER(D5)),NOT(ISNUMBER(E5))),"",(E5 - D5) / D5) -> -0.036
A6: NNOX | B6: Nano-X Imaging Ltd. | C6: 46105 | D6: 2.4 | E6: 2.4 | F6: =IF(OR(D6=0,NOT(ISNUMBER(D6)),NOT(ISNUMBER(E6))),"",(E6 - D6) / D6) -> 0
A7: NNOX | B7: Nano-X Imaging Ltd. | C7: 46106 | D7: 2.42 | E7: 2.29 | F7: =IF(OR(D7=0,NOT(ISNUMBER(D7)),NOT(ISNUMBER(E7))),"",(E7 - D7) / D7) -> -0.053719008
A8: NNOX | B8: Nano-X Imaging Ltd. | C8: 46107 | D8: 2.27 | E8: 2.27 | F8: =IF(OR(D8=0,NOT(ISNUMBER(D8)),NOT(ISNUMBER(E8))),"",(E8 - D8) / D8) -> 0
A9: NNOX | B9: Nano-X Imaging Ltd. | C9: 46108 | D9: 2.28 | E9: 2.21 | F9: =IF(OR(D9=0,NOT(ISNUMBER(D9)),NOT(ISNUMBER(E9))),"",(E9 - D9) / D9) -> -0.030701754
A10: NNOX | B10: Nano-X Imaging Ltd. | C10: 46112 | D10: 2.22 | E10: 2.2 | F10: =IF(OR(D10=0,NOT(ISNUMBER(D10)),NOT(ISNUMBER(E10))),"",(E10 - D10) / D10) -> -0.009009009 | G10: Period Low
A11: NNOX | B11: Nano-X Imaging Ltd. | C11: 46113 | D11: 2.2 | E11: 2.27 | F11: =IF(OR(D11=0,NOT(ISNUMBER(D11)),NOT(ISNUMBER(E11))),"",(E11 - D11) / D11) -> 0.031818182 | G11: Bounce
A12: NNOX | B12: Nano-X Imaging Ltd. | C12: 46114 | D12: 2.34 | E12: 2.41 | F12: =IF(OR(D12=0,NOT(ISNUMBER(D12)),NOT(ISNUMBER(E12))),"",(E12 - D12) / D12) -> 0.02991453
A13: NNOX | B13: Nano-X Imaging Ltd. | C13: 46115 | D13: 2.37 | E13: 2.41 | F13: =IF(OR(D13=0,NOT(ISNUMBER(D13)),NOT(ISNUMBER(E13))),"",(E13 - D13) / D13) -> 0.016877637
A14: NNOX | B14: Nano-X Imaging Ltd. | C14: 46119 | D14: 2.44 | E14: 2.37 | F14: =IF(OR(D14=0,NOT(ISNUMBER(D14)),NOT(ISNUMBER(E14))),"",(E14 - D14) / D14) -> -0.028688525
A15: NNOX | B15: Nano-X Imaging Ltd. | C15: 46120 | D15: 2.35 | E15: 2.3 | F15: =IF(OR(D15=0,NOT(ISNUMBER(D15)),NOT(ISNUMBER(E15))),"",(E15 - D15) / D15) -> -0.021276596
A16: NNOX | B16: Nano-X Imaging Ltd. | C16: 46121 | D16: 2.41 | E16: 2.33 | F16: =IF(OR(D16=0,NOT(ISNUMBER(D16)),NOT(ISNUMBER(E16))),"",(E16 - D16) / D16) -> -0.033195021
A17: NNOX | B17: Nano-X Imaging Ltd. | C17: 46122 | D17: 2.31 | E17: 2.32 | F17: =IF(OR(D17=0,NOT(ISNUMBER(D17)),NOT(ISNUMBER(E17))),"",(E17 - D17) / D17) -> 0.0043290043
A18: NNOX | B18: Nano-X Imaging Ltd. | C18: 46123 | D18: 2.34 | E18: 2.27 | F18: =IF(OR(D18=0,NOT(ISNUMBER(D18)),NOT(ISNUMBER(E18))),"",(E18 - D18) / D18) -> -0.02991453
A19: NNOX | B19: Nano-X Imaging Ltd. | C19: 46126 | D19: 2.29 | E19: 2.38 | F19: =IF(OR(D19=0,NOT(ISNUMBER(D19)),NOT(ISNUMBER(E19))),"",(E19 - D19) / D19) -> 0.03930131 | G19: Bounce
A20: NNOX | B20: Nano-X Imaging Ltd. | C20: 46127 | D20: 2.45 | E20: 2.47 | F20: =IF(OR(D20=0,NOT(ISNUMBER(D20)),NOT(ISNUMBER(E20))),"",(E20 - D20) / D20) -> 0.0081632653
A21: NNOX | B21: Nano-X Imaging Ltd. | C21: 46128 | D21: 2.49 | E21: 2.59 | F21: =IF(OR(D21=0,NOT(ISNUMBER(D21)),NOT(ISNUMBER(E21))),"",(E21 - D21) / D21) -> 0.040160643 | G21: Full recovery to start price
C24: Period Start: | D24: End: | E24: Pct Change | F24: Low: $2.20 (Mar 31) • High: $2.60 (Mar 17). Flat.
C25: 2.57 | D25: 2.59 | E25: =IF(OR(C25=0,NOT(ISNUMBER(C25)),NOT(ISNUMBER(D25))),"",(D25 - C25) / C25) -> 0.0077821012

Sheet FSLY
A1: Ticker Name | B1: Company | C1: Date | D1: Open | E1: Close | F1: % Change | G1: Notes
A2: FSLY | B2: Fastly Inc. | C2: 46098 | D2: 22.27 | E2: 24.18 | F2: =IF(OR(D2=0,NOT(ISNUMBER(D2)),NOT(ISNUMBER(E2))),"",(E2 - D2) / D2) -> 0.085765604 | G2: Strong open
A3: FSLY | B3: Fastly Inc. | C3: 46099 | D3: 24.03 | E3: 26.88 | F3: =IF(OR(D3=0,NOT(ISNUMBER(D3)),NOT(ISNUMBER(E3))),"",(E3 - D3) / D3) -> 0.11860175 | G3: Massive surge
A4: FSLY | B4: Fastly Inc. | C4: 46100 | D4: 26.57 | E4: 26.45 | F4: =IF(OR(D4=0,NOT(ISNUMBER(D4)),NOT(ISNUMBER(E4))),"",(E4 - D4) / D4) -> -0.0045163718
A5: FSLY | B5: Fastly Inc. | C5: 46101 | D5: 26.48 | E5: 25.2 | F5: =IF(OR(D5=0,NOT(ISNUMBER(D5)),NOT(ISNUMBER(E5))),"",(E5 - D5) / D5) -> -0.048338369 | G5: Quad witching pressure
A6: FSLY | B6: Fastly Inc. | C6: 46105 | D6: 28.55 | E6: 28.2 | F6: =IF(OR(D6=0,NOT(ISNUMBER(D6)),NOT(ISNUMBER(E6))),"",(E6 - D6) / D6) -> -0.012259194 | G6: Gap-up continuation
A7: FSLY | B7: Fastly Inc. | C7: 46106 | D7: 29.47 | E7: 29.79 | F7: =IF(OR(D7=0,NOT(ISNUMBER(D7)),NOT(ISNUMBER(E7))),"",(E7 - D7) / D7) -> 0.0108585
A8: FSLY | B8: Fastly Inc. | C8: 46107 | D8: 29.5 | E8: 28.59 | F8: =IF(OR(D8=0,NOT(ISNUMBER(D8)),NOT(ISNUMBER(E8))),"",(E8 - D8) / D8) -> -0.030847458
A9: FSLY | B9: Fastly Inc. | C9: 46108 | D9: 28.1 | E9: 27.43 | F9: =IF(OR(D9=0,NOT(ISNUMBER(D9)),NOT(ISNUMBER(E9))),"",(E9 - D9) / D9) -> -0.023843416
A10: FSLY | B10: Fastly Inc. | C10: 46112 | D10: 28.43 | E10: 25.52 | F10: =IF(OR(D10=0,NOT(ISNUMBER(D10)),NOT(ISNUMBER(E10))),"",(E10 - D10) / D10) -> -0.10235667
A11: FSLY | B11: Fastly Inc. | C11: 46113 | D11: 26.08 | E11: 29.06 | F11: =IF(OR(D11=0,NOT(ISNUMBER(D11)),NOT(ISNUMBER(E11))),"",(E11 - D11) / D11) -> 0.1142638 | G11: Massive bounce
A12: FSLY | B12: Fastly Inc. | C12: 46114 | D12: 29.98 | E12: 32.36 | F12: =IF(OR(D12=0,NOT(ISNUMBER(D12)),NOT(ISNUMBER(E12))),"",(E12 - D12) / D12) -> 0.079386258
A13: FSLY | B13: Fastly Inc. | C13: 46115 | D13: 30.8 | E13: 33.5 | F13: =IF(OR(D13=0,NOT(ISNUMBER(D13)),NOT(ISNUMBER(E13))),"",(E13 - D13) / D13) -> 0.087662338 | G13: Period High
A14: FSLY | B14: Fastly Inc. | C14: 46119 | D14: 33.94 | E14: 31.54 | F14: =IF(OR(D14=0,NOT(ISNUMBER(D14)),NOT(ISNUMBER(E14))),"",(E14 - D14) / D14) -> -0.070713023 | G14: Reversal begins
A15: FSLY | B15: Fastly Inc. | C15: 46120 | D15: 31.63 | E15: 31.6 | F15: =IF(OR(D15=0,NOT(ISNUMBER(D15)),NOT(ISNUMBER(E15))),"",(E15 - D15) / D15) -> -0.00094846665
A16: FSLY | B16: Fastly Inc. | C16: 46121 | D16: 34.05 | E16: 32.75 | F16: =IF(OR(D16=0,NOT(ISNUMBER(D16)),NOT(ISNUMBER(E16))),"",(E16 - D16) / D16) -> -0.038179148
A17: FSLY | B17: Fastly Inc. | C17: 46122 | D17: 32.74 | E17: 29.46 | F17: =IF(OR(D17=0,NOT(ISNUMBER(D17)),NOT(ISNUMBER(E17))),"",(E17 - D17) / D17) -> -0.10018326 | G17: Sharp selloff
A18: FSLY | B18: Fastly Inc. | C18: 46123 | D18: 30.02 | E18: 23.07 | F18: =IF(OR(D18=0,NOT(ISNUMBER(D18)),NOT(ISNUMBER(E18))),"",(E18 - D18) / D18) -> -0.23151233 | G18: Crash day. –21.7%
A19: FSLY | B19: Fastly Inc. | C19: 46126 | D19: 23.1 | E19: 24.37 | F19: =IF(OR(D19=0,NOT(ISNUMBER(D19)),NOT(ISNUMBER(E19))),"",(E19 - D19) / D19) -> 0.054978355 | G19: Dead cat bounce
A20: FSLY | B20: Fastly Inc. | C20: 46127 | D20: 24.52 | E20: 20.95 | F20: =IF(OR(D20=0,NOT(ISNUMBER(D20)),NOT(ISNUMBER(E20))),"",(E20 - D20) / D20) -> -0.14559543 | G20: Period Low. Continued crash.
A21: FSLY | B21: Fastly Inc. | C21: 46128 | D21: 21.76 | E21: 23.38 | F21: =IF(OR(D21=0,NOT(ISNUMBER(D21)),NOT(ISNUMBER(E21))),"",(E21 - D21) / D21) -> 0.074448529 | G21: Recovery bounce
C23: Period Start: | D23: End: | E23: Pct Change | F23: Low: $20.95 (Apr 15) • High: $33.50 (Apr 3). EXTREME volatility.
C24: 22.27 | D24: 23.38 | E24: =IF(OR(C24=0,NOT(ISNUMBER(C24)),NOT(ISNUMBER(D24))),"",(D24 - C24) / C24) -> 0.049842838

Sheet Pivot Data
A2: FSLY | G2: NNOX | M2: COUR | S2: EVGO
A3: Date | B3: Open Price | C3: Close Price | D3: Pct Change | G3: Date | H3: Open Price | I3: Close Price | J3: Pct Change | M3: Date | N3: Open Price | O3: Close Price | P3: Pct Change | S3: Date | T3: Open Price | U3: Close PRice | V3: Pct Change
A4: 17-Mar | B4: 22.27 | C4: 24.18 | D4: 0.085765604 | G4: 17-Mar | H4: 2.57 | I4: 2.6 | J4: 0.011673152 | M4: 17-Mar | N4: 6.1 | O4: 6.07 | P4: -0.0049180328 | S4: 17-Mar | T4: 2.11 | U4: 2.06 | V4: -0.023696682
A5: 18-Mar | B5: 24.03 | C5: 26.88 | D5: 0.11860175 | G5: 18-Mar | H5: 2.56 | I5: 2.46 | J5: -0.0390625 | M5: 18-Mar | N5: 5.96 | O5: 5.86 | P5: -0.016778523 | S5: 18-Mar | T5: 2.05 | U5: 1.93 | V5: -0.058536585
A6: 19-Mar | B6: 26.57 | C6: 26.45 | D6: -0.0045163718 | G6: 19-Mar | H6: 2.42 | I6: 2.51 | J6: 0.037190083 | M6: 19-Mar | N6: 5.81 | O6: 6.04 | P6: 0.039586919 | S6: 19-Mar | T6: 1.9 | U6: 2.05 | V6: 0.078947368
A7: 20-Mar | B7: 26.48 | C7: 25.2 | D7: -0.048338369 | G7: 20-Mar | H7: 2.5 | I7: 2.41 | J7: -0.036 | M7: 20-Mar | N7: 6 | O7: 5.84 | P7: -0.026666667 | S7: 20-Mar | T7: 2.05 | U7: 1.94 | V7: -0.053658537
A8: 24-Mar | B8: 28.55 | C8: 28.2 | D8: -0.012259194 | G8: 24-Mar | H8: 2.4 | I8: 2.4 | J8: 0 | M8: 24-Mar | N8: 5.87 | O8: 5.69 | P8: -0.030664395 | S8: 24-Mar | T8: 1.93 | U8: 1.87 | V8: -0.031088083
A9: 25-Mar | B9: 29.47 | C9: 29.79 | D9: 0.0108585 | G9: 25-Mar | H9: 2.42 | I9: 2.29 | J9: -0.053719008 | M9: 25-Mar | N9: 5.81 | O9: 5.87 | P9: 0.010327022 | S9: 25-Mar | T9: 1.85 | U9: 1.81 | V9: -0.021621622
A10: 26-Mar | B10: 29.5 | C10: 28.59 | D10: -0.030847458 | G10: 26-Mar | H10: 2.27 | I10: 2.27 | J10: 0 | M10: 26-Mar | N10: 5.8 | O10: 5.84 | P10: 0.0068965517 | S10: 26-Mar | T10: 1.77 | U10: 1.75 | V10: -0.011299435
A11: 27-Mar | B11: 28.1 | C11: 27.43 | D11: -0.023843416 | G11: 27-Mar | H11: 2.28 | I11: 2.21 | J11: -0.030701754 | M11: 27-Mar | N11: 5.74 | O11: 5.51 | P11: -0.040069686 | S11: 27-Mar | T11: 1.72 | U11: 1.72 | V11: 0
A12: 31-Mar | B12: 28.43 | C12: 25.52 | D12: -0.10235667 | G12: 31-Mar | H12: 2.22 | I12: 2.2 | J12: -0.009009009 | M12: 31-Mar | N12: 5.59 | O12: 5.73 | P12: 0.025044723 | S12: 31-Mar | T12: 1.73 | U12: 1.66 | V12: -0.040462428
A13: 1-Apr | B13: 26.08 | C13: 29.06 | D13: 0.1142638 | G13: 1-Apr | H13: 2.2 | I13: 2.27 | J13: 0.031818182 | M13: 1-Apr | N13: 5.8 | O13: 5.82 | P13: 0.0034482759 | S13: 1-Apr | T13: 1.67 | U13: 1.72 | V13: 0.02994012
A14: 2-Apr | B14: 29.98 | C14: 32.36 | D14: 0.079386258 | G14: 2-Apr | H14: 2.34 | I14: 2.41 | J14: 0.02991453 | M14: 2-Apr | N14: 5.78 | O14: 5.85 | P14: 0.012110727 | S14: 2-Apr | T14: 1.75 | U14: 1.77 | V14: 0.011428571
A15: 3-Apr | B15: 30.8 | C15: 33.5 | D15: 0.087662338 | G15: 3-Apr | H15: 2.37 | I15: 2.41 | J15: 0.016877637 | M15: 3-Apr | N15: 5.75 | O15: 5.91 | P15: 0.027826087 | S15: 3-Apr | T15: 1.72 | U15: 1.71 | V15: -0.0058139535
... A23: 16-Apr | B23: 21.76 | C23: 23.38 | D23: 0.074448529 | G23: 16-Apr | H23: 2.49 | I23: 2.59 | J23: 0.040160643 | M23: 16-Apr | N23: 6.03 | O23: 6.15 | P23: 0.019900498 | S23: 16-Apr | T23: 2.05 | U23: 2.06 | V23: 0.0048780488
A28: BLDP | G28: RUN | M28: STEM | S28: MNDY
A29: Date | B29: Open Price | C29: Close Price | D29: Pct Change | G29: Date | H29: Open Price | I29: Close Price | J29: Pct Change | M29: Date | N29: Open Price | O29: Close Price | P29: Pct Change | S29: Date | T29: Open Price | U29: Close Price | V29: Pct Change
A30: 17-Mar | B30: 2.56 | C30: 2.68 | D30: 0.046875 | G30: 17-Mar | H30: 12.93 | I30: 13.29 | J30: 0.027842227 | M30: 17-Mar | N30: 10.94 | O30: 10.9 | P30: -0.0036563071 | S30: 17-Mar | T30: 74.43 | U30: 75.28 | V30: 0.011420126
A31: 18-Mar | B31: 2.64 | C31: 2.61 | D31: -0.011363636 | G31: 18-Mar | H31: 13.37 | I31: 12.79 | J31: -0.043380703 | M31: 18-Mar | N31: 10.66 | O31: 10.59 | P31: -0.0065666041 | S31: 18-Mar | T31: 74.24 | U31: 73.97 | V31: -0.0036368534
A32: 19-Mar | B32: 2.51 | C32: 2.48 | D32: -0.011952191 | G32: 19-Mar | H32: 12.52 | I32: 13.08 | J32: 0.044728435 | M32: 19-Mar | N32: 10.31 | O32: 10.46 | P32: 0.014548982 | S32: 19-Mar | T32: 73.8 | U32: 74.73 | V32: 0.012601626
A33: 20-Mar | B33: 2.47 | C33: 2.41 | D33: -0.024291498 | G33: 20-Mar | H33: 13.05 | I33: 12.22 | J33: -0.063601533 | M33: 20-Mar | N33: 10.42 | O33: 9.7 | P33: -0.069097889 | S33: 20-Mar | T33: 74.36 | U33: 73.85 | V33: -0.0068585261
A34: 24-Mar | B34: 2.47 | C34: 2.46 | D34: -0.004048583 | G34: 24-Mar | H34: 12.42 | I34: 12.75 | J34: 0.026570048 | M34: 24-Mar | N34: 9.99 | O34: 9.99 | P34: 0 | S34: 24-Mar | T34: 74.31 | U34: 72.37 | V34: -0.02610685
A35: 25-Mar | B35: 2.5 | C35: 2.54 | D35: 0.016 | G35: 25-Mar | H35: 12.95 | I35: 13.04 | J35: 0.0069498069 | M35: 25-Mar | N35: 10.1 | O35: 10.47 | P35: 0.036633663 | S35: 25-Mar | T35: 74.79 | U35: 69.28 | V35: -0.073672951
A36: 26-Mar | B36: 2.49 | C36: 2.45 | D36: -0.016064257 | G36: 26-Mar | H36: 12.74 | I36: 12.4 | J36: -0.026687598 | M36: 26-Mar | N36: 10.22 | O36: 9.72 | P36: -0.048923679 | S36: 26-Mar | T36: 68.55 | U36: 69.38 | V36: 0.01210795
A37: 27-Mar | B37: 2.41 | C37: 2.39 | D37: -0.0082987552 | G37: 27-Mar | H37: 12.19 | I37: 12.6 | J37: 0.033634126 | M37: 27-Mar | N37: 9.41 | O37: 8.75 | P37: -0.070138151 | S37: 27-Mar | T37: 67.75 | U37: 66.47 | V37: -0.018892989
A38: 31-Mar | B38: 2.42 | C38: 2.3 | D38: -0.049586777 | G38: 31-Mar | H38: 12.89 | I38: 12.14 | J38: -0.058184639 | M38: 31-Mar | N38: 8.79 | O38: 8.25 | P38: -0.061433447 | S38: 31-Mar | T38: 67.01 | U38: 67.88 | V38: 0.012983137
A39: 1-Apr | B39: 2.32 | C39: 2.42 | D39: 0.043103448 | G39: 1-Apr | H39: 12.53 | I39: 13.56 | J39: 0.082202713 | M39: 1-Apr | N39: 8.47 | O39: 8.84 | P39: 0.043683589 | S39: 1-Apr | T39: 68.9 | U39: 69.11 | V39: 0.0030478955
A40: 2-Apr | B40: 2.44 | C40: 2.41 | D40: -0.012295082 | G40: 2-Apr | H40: 13.8 | I40: 14.15 | J40: 0.025362319 | M40: 2-Apr | N40: 8.94 | O40: 8.83 | P40: -0.012304251 | S40: 2-Apr | T40: 69.95 | U40: 68.1 | V40: -0.026447462
A41: 3-Apr | B41: 2.35 | C41: 2.48 | D41: 0.055319149 | G41: 3-Apr | H41: 13.63 | I41: 13.5 | J41: -0.0095377843 | M41: 3-Apr | N41: 8.39 | O41: 8.66 | P41: 0.032181168 | S41: 3-Apr | T41: 68.1 | U41: 68.34 | V41: 0.0035242291
... A49: 16-Apr | B49: 2.98 | C49: 3.07 | D49: 0.030201342 | G49: 16-Apr | H49: 12.59 | I49: 12.1 | J49: -0.038919778 | M49: 16-Apr | N49: 10.52 | O49: 10.75 | P49: 0.021863118 | S49: 16-Apr | T49: 64.4 | U49: 65.43 | V49: 0.015993789
A53: DXCM | G53: NVDA
A54: Date | B54: Open Price | C54: Close Price | D54: Pct Change | G54: Date | H54: Open Price | I54: Close Price | J54: Pct Change
A55: 17-Mar | B55: 67.11 | C55: 67.32 | D55: 0.0031291909 | G55: 17-Mar | H55: 185.06 | I55: 181.93 | J55: -0.016913433
A56: 18-Mar | B56: 66.72 | C56: 67.66 | D56: 0.014088729 | G56: 18-Mar | H56: 182.48 | I56: 180.4 | J56: -0.011398509
A57: 19-Mar | B57: 67.98 | C57: 67.27 | D57: -0.010444248 | G57: 19-Mar | H57: 178.01 | I57: 178.56 | J57: 0.0030897141
A58: 20-Mar | B58: 67.42 | C58: 66.95 | D58: -0.0069712252 | G58: 20-Mar | H58: 178 | I58: 172.7 | J58: -0.029775281
A59: 24-Mar | B59: 66.31 | C59: 66.6 | D59: 0.0043733977 | G59: 24-Mar | H59: 174.83 | I59: 175.2 | J59: 0.0021163416
A60: 25-Mar | B60: 67.22 | C60: 66.84 | D60: -0.0056530794 | G60: 25-Mar | H60: 177.1 | I60: 178.68 | J60: 0.0089215133
A61: 26-Mar | B61: 66.84 | C61: 66.09 | D61: -0.011220826 | G61: 26-Mar | H61: 176.07 | I61: 171.24 | J61: -0.027432271
A62: 27-Mar | B62: 65.91 | C62: 62.25 | D62: -0.055530269 | G62: 27-Mar | H62: 170 | I62: 167.52 | J62: -0.014588235
...

Sheet Ranking Performance
A1: Rank | B1: Ticker Name | C1: Company | D1: Start (Mar 16 Close) | E1: End (Apr 15 Close) | F1: Period Return
A2: 1 | B2: BLDP | C2: Ballard Power Systems | D2: 2.56 | E2: 3.07 | F2: =IF(OR(D2=0,NOT(ISNUMBER(D2)),NOT(ISNUMBER(E2))),"",(E2 - D2) / D2) -> 0.19921875
A3: 2 | B3: NVDA | C3: NVIDIA Corporation | D3: 185.06 | E3: 198.87 | F3: =IF(OR(D3=0,NOT(ISNUMBER(D3)),NOT(ISNUMBER(E3))),"",(E3 - D3) / D3) -> 0.074624446
A4: 3 | B4: FSLY | C4: Fastly Inc. | D4: 22.27 | E4: 23.38 | F4: =IF(OR(D4=0,NOT(ISNUMBER(D4)),NOT(ISNUMBER(E4))),"",(E4 - D4) / D4) -> 0.049842838
A5: 4 | B5: COUR | C5: Coursera Inc. | D5: 6.1 | E5: 6.15 | F5: =IF(OR(D5=0,NOT(ISNUMBER(D5)),NOT(ISNUMBER(E5))),"",(E5 - D5) / D5) -> 0.0081967213
A6: 5 | B6: NNOX | C6: Nano-X Imaging | D6: 2.57 | E6: 2.59 | F6: =IF(OR(D6=0,NOT(ISNUMBER(D6)),NOT(ISNUMBER(E6))),"",(E6 - D6) / D6) -> 0.0077821012
A7: 6 | B7: STEM | C7: Stem Inc. | D7: 10.94 | E7: 10.75 | F7: =IF(OR(D7=0,NOT(ISNUMBER(D7)),NOT(ISNUMBER(E7))),"",(E7 - D7) / D7) -> -0.017367459
A8: 7 | B8: EVGO | C8: EVgo Inc. | D8: 2.11 | E8: 2.06 | F8: =IF(OR(D8=0,NOT(ISNUMBER(D8)),NOT(ISNUMBER(E8))),"",(E8 - D8) / D8) -> -0.023696682
A9: 8 | B9: RUN | C9: Sunrun Inc. | D9: 12.93 | E9: 12.1 | F9: =IF(OR(D9=0,NOT(ISNUMBER(D9)),NOT(ISNUMBER(E9))),"",(E9 - D9) / D9) -> -0.064191802
A10: 9 | B10: DXCM | C10: DexCom Inc. | D10: 67.11 | E10: 61.54 | F10: =IF(OR(D10=0,NOT(ISNUMBER(D10)),NOT(ISNUMBER(E10))),"",(E10 - D10) / D10) -> -0.082998063
A11: 10 | B11: MNDY | C11: monday.com Ltd. | D11: 74.43 | E11: 65.43 | F11: =IF(OR(D11=0,NOT(ISNUMBER(D11)),NOT(ISNUMBER(E11))),"",(E11 - D11) / D11) -> -0.12091898

Sheet Performance Graphs
